Workbook

Sheet Iyer Sir Room Maintenance
A1: Iyer Sir Room Maintenance
B3: Maintenance rate till July 2022 | D3: 1 Rs. / Sq. Ft.
B4: Maintenance from Aug 2022 | D4: 1 RK - 800 Rs. 1 BHK - 1000 Rs. 2 BHK - 1100 Rs.
B7: Flat No | C7: Area(Sq. Ft.) | D7: Move In Month | E7: Particulars | F7: Total
B8: 101 | C8: 350(1 RK) | D8: 44713 | E8: June - July -> Rs. 700 Aug - Sep -> Rs. 1600 | F8: 2300
B9: 103 | C9: 550(1 BHK) | D9: 44713 | E9: June - July -> Rs. 1100 Aug - Sep -> Rs. 2000 | F9: 3100
B10: 104 | C10: 560(1 BHK) | D10: 44682 | E10: May - July -> Rs. 1680 Aug - Sep -> Rs. 2000 | F10: 3680
B11: 105 | C11: 400(1 RK) | D11: 44713 | E11: June - July -> Rs. 800 Aug - Sep -> Rs. 1600 | F11: 2400
B12: 202 | C12: 775(2 BHK) | D12: 44774 | E12: Aug - Sep -> Rs. 2200 | F12: 2200
B13: 206 | C13: 570(1 BHK) | D13: 44743 | E13: July -> Rs. 570 Aug - Sep -> Rs. 2000 | F13: 2570
B14: 304 | C14: 560(1 BHK) | D14: 44713 | E14: June - July -> Rs. 1200 Aug - Sep -> Rs. 2000 | F14: 3200
B15: 305 | C15: 400(1 RK) | D15: 44713 | E15: June - July -> Rs. 800 Aug - Sep -> Rs. 1600 | F15: 2400
B16: 406 | C16: 570(1 BHK) | D16: 44743 | E16: July -> Rs. 570 Aug - Sep -> Rs. 2000 | F16: 2570
B17: 407 | C17: 550(1 BHK) | D17: 44713 | E17: June - July -> Rs. 1100 Aug - Sep -> Rs. 2000 | F17: 3100
B18: 501 | C18: 350(1 RK) | D18: 44774 | E18: Aug - Sep -> Rs. 1600 | F18: 1600
B19: 503 | C19: 550(1 BHK) | D19: 44774 | E19: Aug - Sep -> Rs. 2000 | F19: 2000
... B21: 506 | C21: 570(1 BHK) | D21: 44774 | E21: Aug - Sep -> Rs. 2000 | F21: 2000
E22: Total | F22: =SUM(F8:F21) -> 35520

Sheet Maintenance_rebalancing
A1: M/s Bhavani Paradise
A2: Bhavani Paradise, Ravikiran society, Chera Nagar, Manpada rd., Dombivli East - 421 201
A3: Monthly Maintenance
A4: Flat No \ Month-Year | B4: 102 | C4: 201 | D4: 203 | E4: 204 | F4: 205 | G4: 207 | H4: 301 | I4: 302 | J4: 303 | K4: 306 | L4: 307 | M4: 401 | N4: 405 | O4: Total
A5: 44337 | B5: 275 | C5: -150 | D5: 550 | E5: 560 | F5: -100 | H5: -150 | I5: 225 | J5: 50 | K5: 70 | L5: 550 | M5: -150 | N5: -100 | O5: =SUM(B5:N5) -> 1630
A6: 44368 | B6: 275 | C6: -150 | D6: 550 | E6: 560 | F6: -100 | H6: -150 | I6: 225 | J6: 50 | K6: 70 | L6: 550 | M6: -150 | N6: -100 | O6: =SUM(B6:N6) -> 1630
A7: 44398 | B7: 275 | C7: -150 | D7: 550 | E7: 560 | F7: -100 | H7: -350 | I7: -225 | J7: 50 | K7: 70 | L7: 550 | M7: -150 | N7: -100 | O7: =SUM(B7:N7) -> 980
A8: 44429 | B8: 275 | C8: -150 | D8: 550 | E8: 560 | F8: -100 | H8: -350 | I8: -225 | J8: 50 | K8: 70 | L8: 550 | M8: -350 | N8: -100 | O8: =SUM(B8:N8) -> 780
A9: 44460 | B9: 275 | C9: -350 | D9: 550 | E9: 560 | F9: -400 | H9: -350 | I9: -225 | J9: 50 | K9: 70 | L9: 550 | M9: -350 | N9: -100 | O9: =SUM(B9:N9) -> 280
A10: 44490 | B10: 275 | C10: -350 | D10: 550 | E10: 560 | F10: -400 | H10: -350 | I10: -225 | J10: 50 | K10: 70 | L10: 550 | M10: -350 | N10: -100 | O10: =SUM(B10:N10) -> 280
A11: 44521 | B11: 275 | C11: -350 | D11: 550 | E11: 560 | F11: -400 | H11: -350 | I11: -225 | J11: 50 | K11: 70 | L11: 550 | M11: -350 | N11: -100 | O11: =SUM(B11:N11) -> 280
A12: 44551 | B12: 275 | C12: -350 | D12: 550 | E12: 560 | F12: -400 | G12: -150 | H12: -350 | I12: -225 | J12: 50 | K12: 70 | L12: 550 | M12: -350 | N12: -100 | O12: =SUM(B12:N12) -> 130
A13: 44582 | B13: 275 | C13: -350 | D13: 550 | E13: 560 | F13: -400 | G13: -150 | H13: -350 | I13: -225 | J13: 50 | K13: 70 | L13: 550 | M13: -350 | N13: -100 | O13: =SUM(B13:N13) -> 130
A14: 44613 | B14: 275 | C14: -350 | D14: 550 | E14: 560 | F14: -400 | G14: -150 | H14: -350 | I14: -225 | J14: 50 | K14: 70 | L14: 550 | M14: -350 | N14: -100 | O14: =SUM(B14:N14) -> 130
A15: 44641 | B15: 275 | C15: -350 | D15: 550 | E15: 560 | F15: -400 | G15: -150 | H15: -350 | I15: -225 | J15: 50 | K15: 70 | L15: 550 | M15: -350 | N15: -100 | O15: =SUM(B15:N15) -> 130
O16: =SUM(B16:N16) -> 0
O17: =SUM(B17:N17) -> 0
O18: =SUM(B18:N18) -> 0
O19: =SUM(B19:N19) -> 0
O20: =SUM(B20:N20) -> 0
O21: =SUM(B21:N21) -> 0
O22: =SUM(B22:N22) -> 0
O23: =SUM(B23:N23) -> 0
A24: Total | B24: =SUM(B5:B23) -> 3025 | C24: =SUM(C5:C23) -> -3050 | D24: =SUM(D5:D23) -> 6050 | E24: =SUM(E5:E23) -> 6160 | F24: =SUM(F5:F23) -> -3200 | G24: =SUM(G5:G23) -> -600 | H24: =SUM(H5:H23) -> -3450 | I24: =SUM(I5:I23) -> -1575 | ... O24: =SUM(O5:O23) -> 6380

Sheet Summary
A1: ca
A2: Bhavani Paradise, Ravikiran society, Chera Nagar, Manpada rd., Dombivli East - 421 201 | F2: Debits
C3: Credits | F3: Sr no. | G3: Description | H3: Amount
A4: Sr no. | B4: Flat no. | C4: Name | D4: Maintainance Paid ( From April 21 - Till Date ) | L4: Total Expenses | M4: Maintenance Income | N4: Other Income | O4: Society Dues | P4: Balance
A5: 1 | B5: 101 | C5: Mr. & Mrs. Sawant | D5: =Maintenance!G5+#REF!+#REF!+#REF! -> #REF! | L5: =VLOOKUP(Expenses!C276,Expenses!C:D,2) -> 1202585 | M5: {=INDEX(Maintenance!1:1056,MATCH(Maintenance!A84,Maintenance!A:A),MATCH(Maintenance!U4,Maintenance!4:4))} -> 605920 | N5: =VLOOKUP(Income!C36,Income!C:D,2) -> 432868 | O5: =Income!J36 -> 0 | P5: =M5+N5+O5+-L5 -> -163797
A6: =A5+1 -> 2 | B6: 201 | C6: Mr. & Mrs. Sonar | D6: =Maintenance!G6+#REF!+#REF!+#REF! -> #REF!
A7: =A6+1 -> 3 | B7: 205 | C7: Mr. Lokesh & family | D7: =Maintenance!G7+#REF!+#REF!+#REF! -> #REF!
A8: =A7+1 -> 4 | B8: 301 | C8: Mr. & Mrs.Kamble | D8: =Maintenance!G8+#REF!+#REF!+#REF! -> #REF!
A9: =A8+1 -> 5 | B9: 302 | C9: Mr. & Mrs. Vyas | D9: =Maintenance!G9+#REF!+#REF!+#REF! -> #REF!
A10: =A9+1 -> 6 | B10: 303 | C10: Mr. & Mrs. Vyas | D10: =Maintenance!G10+#REF!+#REF!+#REF! -> #REF!
A11: =A10+1 -> 7 | B11: 306 | C11: Mr. & Mrs. Kadam | D11: =Maintenance!G11+#REF!+#REF!+#REF! -> #REF!
A12: =A11+1 -> 8 | B12: 401 | C12: Mr. & Mrs. Gadekar | D12: =Maintenance!G12+#REF!+#REF!+#REF! -> #REF!
A13: =A12+1 -> 9 | B13: 405 | C13: Mr Vyas Family | D13: =Maintenance!G13+#REF!+#REF!+#REF! -> #REF!
A15: Total Maintainance | D15: =SUM(D5:D14) -> #REF! | F15: Total Expense | H15: =Maintenance!L84+#REF!+#REF!+#REF! -> #REF!
A16: Total Savings | D16: =D15-H15 -> #REF!

Sheet Payments
B2: Property Tax and Water Bill | G2: CCTV Installation Collection
B3: Room No. | C3: Date | D3: Description | E3: Amount | G3: Room No. | H3: Date | I3: Amount
B4: 302 | C4: 44652 | D4: Property Tax for 3 years (2019, 2020, 2021) Water Bill for 2 years (2019, 2020) | E4: 21555 | G4: 102
B5: 401 | C5: 44654 | D5: Property Tax for 3 years (2019, 2020, 2021) | E5: 7350 | G5: 201 | H5: 44723 | I5: 3000
B6: 306 | C6: 44657 | D6: Property Tax for 3 years (2019, 2020, 2021) Water Bill for 2 years (2019, 2020) | E6: 17250 | G6: 203
B7: 301 | C7: 44658 | D7: Property Tax for 3 years (2019, 2020, 2021) Water Bill for 2 years (2019, 2020) | E7: 12630 | G7: 204 | H7: 44906 | I7: 3000
B8: 201 | C8: 44659 | D8: Property Tax for 2 years (2020, 2021) Water Bill for 1 year (2020) | E8: 7540 | G8: 205 | H8: 46080 | I8: 3000
B9: 205 | C9: 44663 | D9: Property Tax for 3 years (2019, 2020, 2021) Water Bill for 2 years (2019, 2020) | E9: 13680 | G9: 207
B10: 102 | C10: 44682 | D10: Property Tax for 3 years (2019, 2020, 2021) | E10: 16275 | G10: 301
B11: 405 | C11: 44683 | D11: Property Tax for 2.6 years (2019(6 Mo), 2020, 2021) Water Bill for 2 years (2019(6 Mo), 2020) | E11: 10960 | G11: 302 | H11: 44749 | I11: 3000
B12: 303 | C12: 44688 | D12: Property Tax for 2.6 years (2019(6 Mo), 2020, 2021) Water Bill for 2 years (2019(6 Mo), 2020) | E12: 13585 | G12: 303 | H12: 44810 | I12: 3000
B13: 401 | C13: 16-Map-22 | D13: Water Bill for 2 years (2019, 2020) | E13: 5280 | G13: 306 | H13: 44745 | I13: 1500
B14: 102 | C14: 44714 | D14: Water Bill for 2 years (2019, 2020) | E14: 5280 | G14: 401 | H14: 44723 | I14: 1500
D15: Total | E15: =SUM(E4:E14) -> 131385 | G15: 405 | H15: 44772 | I15: 3000
G16: 401 | H16: 44745 | I16: 1500
D17: Transfered to builder | G17: 306 | H17: 44766 | I17: 1500
G18: 307 | H18: 44817 | I18: 3000
G19: Iyer Sir Rooms | H19: 44903 | I19: 42000
G20: 402 | H20: 45375 | I20: 3000
H22: Total | I22: =SUM(I4:I21) -> 72000
B23: Property Tax and Water bill
B24: Room No. | C24: Date | D24: 1 Year property tax | E24: 1 Year Water Bill | F24: Paid | G24: Pending
B25: 205 | C25: 45375 | D25: 3000 | E25: 2640 | F25: =SUM(D25,E25) -> 5640 | G25: 0
B26: 204 | C26: 45375 | D26: 4200 | E26: 2400 | F26: =SUM(D26,E26) -> 6600 | G26: 0
B27: 301 | C27: 45375 | D27: 2625 | E27: 2640 | F27: =SUM(D27,E27) -> 5265 | G27: 0
B28: 201 | C28: 45375 | D28: 2625 | E28: 2640 | F28: =SUM(D28,E28) -> 5265 | G28: 0
B29: 402 | C29: 45375 | D29: 5812 | E29: 2640 | F29: =SUM(D29,E29) -> 8452 | G29: 0
B30: 302 | C30: 45375 | D30: 5812 | E30: 2640 | F30: =SUM(D30,E30) -> 8452 | G30: 0
B31: 303 | C31: 45375 | D31: 4125 | E31: 2640 | F31: =SUM(D31,E31) -> 6765 | G31: 0
B32: 405 | C32: 45375 | D32: 3000 | E32: 2640 | F32: =SUM(D32,E32) -> 5640 | G32: 0
B33: 106 | C33: 45375 | D33: 4275 | E33: 2640 | F33: =SUM(D33,E33) -> 6915 | G33: 0
B34: 107 | C34: 45375 | D34: 4125 | E34: 2640 | F34: =SUM(D34,E34) -> 6765 | G34: 0
B35: 403 | C35: 45375 | D35: 4125 | E35: 2640 | F35: =SUM(D35,E35) -> 6765 | G35: 0
B36: 404 | C36: 45375 | D36: 4200 | E36: 2640 | F36: =SUM(D36,E36) -> 6840 | G36: 0
... B39: 1 | C39: 45375 | D39: 2625 | E39: 0 | F39: =SUM(D39,E39) -> 2625 | G39: 0
B40: Builder 4 Gala | C40: 45375 | D40: 10500 | E40: 0 | F40: =SUM(D40,E40) -> 10500 | G40: 0
B41: 101 | D41: 2625 | E41: 2640 | G41: =SUM(D41:E41) -> 5265
B42: 102 | D42: 5812 | E42: 2640 | G42: =SUM(D42:E42) -> 8452
B43: 203 | D43: 4125 | E43: 2640 | G43: =SUM(D43:E43) -> 6765
B44: 206 | D44: 4275 | E44: 2640 | G44: =SUM(D44:E44) -> 6915
...

Sheet Payments Received
B2: Room No. | C2: Date | D2: Description | E2: Amount
B3: 307 | C3: 44749 | D3: Maintenance May 2021 to June 2022 | E3: 7700
B4: 101 | C4: 45256 | D4: 11 months maintenance from Nov 22 to Sep 23 total Rs. 8800 deposited through cash with Amit Vyas. Amount deposited in society account | E4: 8800
B5: 101 | C5: 45424 | D5: 4 Months maintenance from Oct 23 to Jan 24 total Rs. 3200 deposited through cash with Amit Vyas. Amount deposited in society account | E5: 3200
B6: 502 | C6: 45421 | D6: Maintenance deposit Rs. 10000 in society account | E6: 10000
B7: 207 | C7: 45424 | D7: 5 Months maintenace from Oct 22 to Feb 23 total Rs. 5000 deposited through cash with Amit Vyas. Amount deposited in society account. | E7: 5000
B8: 502 | C8: 45439 | D8: Maintenance deposit Rs. 4300 in society account | E8: 4300
B9: 207 | C9: 45607 | D9: 5 Months maintenance from Mar 23 to Jul 23 total Rs. 5000 deposited through cash with Amit Vyas | E9: 5000
B10: 303 | C10: 45678 | D10: 5 Months maintenance from Apr 24 to Aug 24 total Rs. 5000 deposited through UPI with Amit Vyas | E10: 5000
B11: 207 | C11: 45965 | D11: 1 Month maintenancefor Aug 2023 total rs 1000 deposited through cash with Amit Vyas | E11: 1000
B12: 207 | C12: 46007 | D12: 1 Month maintenancefor Sep 2023 total rs 1000 deposited through cash with Amit Vyas | E12: 1000
B13: 207 | C13: 46034 | D13: 1 Month maintenancefor Oct 2023 total rs 1000 deposited through cash with Amit Vyas | E13: 1000
B14: 205 | C14: 46056 | D14: 10000 Transferred to society account for maintenance of June 22 to Dec 23 | E14: 10000
... B25: 207 | C25: 46310 | D25: 1 month maintenance for Jun 2024 total rs 1000 received through cash by Amit Vyas | E25: 1000

Sheet Pending Maintenance
B2: Pending Maintenance | G2: Building Account from May-21
B3: Room No. | C3: Description | D3: Amount | G3: Description | H3: Amount
B4: 102 | C4: Aug-22 to Jun-23 | D4: 12100 | G4: Owners maintenance collection | H4: 181220
B5: 203 | C5: Aug-22 to Jun-23 | D5: 11000 | G5: Iyer sir maintenance collection | H5: 115000
B6: 205 | C6: Jun-22 to Jun-23 | D6: 9600 | G6: Other Income | H6: 68013
B7: 207 | C7: Aug-22 to Jun-23 | D7: 9450 | G7: Total Expenses | H7: 317850
G8: Ravi Kiran Society Maintenance Paid | H8: 17150
G9: Due to Arif Khan | H9: 21070
G10: Balance in society account | H10: 67453
C15: Total | D15: =SUM(D4:D14) -> 42150
Q39: =SUM(B39:P39) -> 0
Q40: =SUM(B40:P40) -> 0
A41: Total | B41: =SUM(B5:B40) -> 615 | C41: =SUM(C5:C40) -> 0 | D41: =SUM(D5:D40) -> 72200 | E41: =SUM(E5:E40) -> 0 | F41: =SUM(F5:F40) -> 0 | G41: =SUM(G5:G40) -> 0 | H41: =SUM(H5:H40) -> 606536 | I41: =SUM(I5:I40) -> 0 | ... Q41: =SUM(Q5:Q40) -> 0

Sheet Maintenance-Iyer
A1: M/s Bhavani Paradise
A2: Bhavani Paradise, Ravikiran society, Chera Nagar, Manpada rd., Dombivli East - 421 201
A3: Monthly Maintenance | S3: Maintenamce Payments
A4: Flat No \ Month-Year | B4: 101 | C4: 103 | D4: 104 | E4: 105 | F4: 202 | G4: 206 | H4: 304 | I4: 305 | J4: 406 | K4: 407 | L4: 501 | M4: 503 | N4: 505 | O4: 506 | P4: Total | S4: Date | T4: Description | U4: Amount
A5: 44702 | D5: 0 | P5: =SUM(B5:O5) -> 0 | S5: 44808 | T5: Cheque 136601 | U5: 30000
A6: 44734 | B6: 350 | C6: 550 | D6: 0 | E6: 400 | H6: 560 | I6: 400 | K6: 550 | N6: 400 | P6: =SUM(B6:O6) -> 3210 | S6: 44879 | T6: Cheque | U6: 35000
A7: 44764 | B7: 350 | C7: 550 | D7: 0 | E7: 400 | G7: 570 | H7: 560 | I7: 400 | J7: 570 | K7: 550 | N7: 400 | P7: =SUM(B7:O7) -> 4350 | S7: 45082 | T7: Cheque | U7: 50000
P8: =SUM(B8:O8) -> 0 | S8: 44658 | T8: Property Tax for 3 years (2019, 2020, 2021) Water Bill for 2 years (2019, 2020) | U8: 12630
P9: =SUM(B9:O9) -> 0
P10: =SUM(B10:O10) -> 0
P11: =SUM(B11:O11) -> 0
P12: =SUM(B12:O12) -> 0
P13: =SUM(B13:O13) -> 0
A14: 44795 | B14: 800 | C14: 1000 | D14: 1000 | E14: 800 | F14: 1100 | G14: 1000 | H14: 1000 | I14: 800 | J14: 1000 | K14: 1000 | L14: 800 | M14: 1000 | N14: 800 | O14: 1000 | P14: =SUM(B14:O14) -> 13100
A15: 44826 | B15: 800 | C15: 1000 | D15: 1000 | E15: 800 | F15: 1100 | G15: 1000 | H15: 1000 | I15: 800 | J15: 1000 | K15: 1000 | L15: 800 | M15: 1000 | N15: 800 | O15: 1000 | P15: =SUM(B15:O15) -> 13100
A16: 44856 | B16: 800 | C16: 1000 | D16: 1000 | E16: 800 | F16: 1100 | G16: 1000 | H16: 1000 | I16: 800 | J16: 1000 | K16: 1000 | L16: 800 | M16: 1000 | N16: 800 | O16: 1000 | P16: =SUM(B16:O16) -> 13100
A17: 44887 | C17: 1000 | D17: 1000 | E17: 800 | F17: 1100 | G17: 1000 | H17: 1000 | I17: 800 | J17: 1000 | K17: 1000 | L17: 800 | M17: 1000 | N17: 800 | O17: 1000 | P17: =SUM(B17:O17) -> 12300
A18: 44917 | C18: 1000 | D18: 1000 | E18: 800 | F18: 1100 | G18: 1000 | H18: 1000 | I18: 800 | J18: 1000 | K18: 1000 | L18: 800 | M18: 1000 | N18: 800 | O18: 1000 | P18: =SUM(B18:O18) -> 12300
A19: 44949 | C19: 1000 | D19: 1000 | E19: 800 | F19: 1100 | G19: 1000 | H19: 1000 | I19: 800 | J19: 1000 | K19: 1000 | L19: 800 | M19: 1000 | N19: 800 | O19: 1000 | P19: =SUM(B19:O19) -> 12300
A20: 44980 | C20: 1000 | D20: 1000 | E20: 800 | F20: 1100 | G20: 1000 | H20: 1000 | I20: 800 | J20: 1000 | K20: 1000 | L20: 800 | M20: 1000 | N20: 800 | O20: 1000 | P20: =SUM(B20:O20) -> 12300
A21: 45008 | C21: 1000 | D21: 1000 | E21: 800 | F21: 1100 | G21: 1000 | H21: 1000 | I21: 800 | J21: 1000 | K21: 1000 | L21: 800 | M21: 1000 | N21: 800 | O21: 1000 | P21: =SUM(B21:O21) -> 12300
A22: 45039 | C22: 1000 | D22: 1000 | E22: 800 | F22: 1100 | H22: 1000 | I22: 800 | J22: 1000 | K22: 1000 | L22: 800 | M22: 1000 | N22: 800 | O22: 1000 | P22: =SUM(B22:O22) -> 11300
A23: 45069 | C23: 1000 | D23: 1000 | E23: 800 | F23: 1100 | H23: 1000 | I23: 800 | J23: 1000 | K23: 1000 | L23: 800 | M23: 1000 | N23: 800 | O23: 1000 | P23: =SUM(B23:O23) -> 11300
A24: 45100 | C24: 1000 | D24: 1000 | E24: 800 | F24: 1100 | H24: 1000 | I24: 800 | J24: 1000 | K24: 1000 | L24: 800 | M24: 1000 | N24: 800 | O24: 1000 | P24: =SUM(B24:O24) -> 11300
A25: 45130 | C25: 1000 | D25: 1000 | E25: 800 | F25: 1100 | H25: 1000 | I25: 800 | J25: 1000 | K25: 1000 | L25: 800 | M25: 1000 | N25: 800 | O25: 1000 | P25: =SUM(B25:O25) -> 11300
A26: 45161 | C26: 1000 | D26: 1000 | E26: 800 | F26: 1100 | H26: 1000 | I26: 800 | J26: 1000 | K26: 1000 | L26: 800 | M26: 1000 | N26: 800 | O26: 1000 | P26: =SUM(B26:O26) -> 11300
A27: 45192 | C27: 1000 | D27: 1000 | E27: 800 | F27: 1100 | H27: 1000 | I27: 800 | J27: 1000 | K27: 1000 | L27: 800 | M27: 1000 | N27: 800 | O27: 1000 | P27: =SUM(B27:O27) -> 11300
A28: 45222 | C28: 1000 | D28: 1000 | E28: 800 | F28: 1100 | H28: 1000 | I28: 800 | J28: 1000 | K28: 1000 | L28: 800 | M28: 1000 | N28: 800 | O28: 1000 | P28: =SUM(B28:O28) -> 11300
A29: 45253 | P29: =SUM(B29:O29) -> 0
A30: 45283 | P30: =SUM(B30:O30) -> 0
A31: 45292
A32: 45323
A33: 45352
A34: 45383
A35: 45413
A36: 45444
A37: 45474
A38: 45505
A39: 45536
A40: 45566
...

Sheet Pending Works
B2: Sr.No. | C2: Description | D2: Amount
B3: 1 | C3: Water tank Lid | D3: 7000
B4: 2 | C4: CCTV | D4: 28000
B5: 3

Sheet Maintenance-Builder
A1: M/s Bhavani Paradise
A2: Bhavani Paradise, Ravikiran society, Chera Nagar, Manpada rd., Dombivli East - 421 201
A3: Monthly Maintenance | K3: Maintenace Payments | O3: Builder Dues
A4: Flat No \ Month-Year | B4: 106 | C4: 107 | D4: 403 | E4: 404 | F4: 504 | G4: 507 | H4: Total | K4: Date | L4: Description | M4: Amount | O4: Date | P4: Description | Q4: Amount
A5: 45017 | E5: 1000 | H5: =SUM(B5:G5) -> 1000 | O5: 45606 | P5: Miscelaneous Expenses | Q5: 96225
A6: 45047 | B6: 1000 | C6: 1000 | D6: 1000 | E6: 1000 | H6: =SUM(B6:G6) -> 4000 | O6: 46082 | P6: 2025 2026 Lift Maintenance | Q6: 20000
A7: 45078 | B7: 1000 | C7: 1000 | D7: 1000 | E7: 1000 | F7: 1000 | G7: 1000 | H7: =SUM(B7:G7) -> 6000 | O7: 46082 | P7: Water Connection | Q7: 80000
A8: 45108 | B8: 1000 | C8: 1000 | D8: 1000 | E8: 1000 | F8: 1000 | G8: 1000 | H8: =SUM(B8:G8) -> 6000 | K8: 44658 | L8: Property Tax for 3 years (2019, 2020, 2021) Water Bill for 2 years (2019, 2020) | M8: 12630 | O8: 46142 | P8: Apr Elec Bill | Q8: 13500
A9: 45139 | B9: 1000 | C9: 1000 | D9: 1000 | E9: 1000 | F9: 1000 | G9: 1000 | H9: =SUM(B9:G9) -> 6000 | O9: 46142 | P9: Bharat Chember cleaning | Q9: 1000
A10: 45170 | B10: 1000 | C10: 1000 | D10: 1000 | E10: 1000 | F10: 1000 | G10: 1000 | H10: =SUM(B10:G10) -> 6000 | O10: 46142 | P10: Back Ground cleaning | Q10: 2500
A11: 45200 | B11: 1000 | C11: 1000 | D11: 1000 | E11: 1000 | F11: 1000 | G11: 1000 | H11: =SUM(B11:G11) -> 6000
A12: 45231 | B12: 1000 | C12: 1000 | D12: 1000 | E12: 1000 | F12: 1000 | G12: 1000 | H12: =SUM(B12:G12) -> 6000
A13: 45261 | B13: 1000 | C13: 1000 | D13: 1000 | E13: 1000 | F13: 1000 | G13: 1000 | H13: =SUM(B13:G13) -> 6000
A14: 45292 | B14: 1000 | C14: 1000 | D14: 1000 | E14: 1000 | F14: 1000 | G14: 1000 | H14: =SUM(B14:G14) -> 6000
A15: 45323 | B15: 1000 | C15: 1000 | D15: 1000 | E15: 1000 | F15: 1000 | G15: 1000 | H15: =SUM(B15:G15) -> 6000
A16: 45352 | B16: 1000 | C16: 1000 | D16: 1000 | E16: 1000 | F16: 1000 | G16: 1000 | H16: =SUM(B16:G16) -> 6000
A17: 45383 | B17: 1000 | C17: 1000 | D17: 1000 | E17: 1000 | F17: 1000 | G17: 1000 | H17: =SUM(B17:G17) -> 6000
A18: 45413 | B18: 1000 | C18: 1000 | D18: 1000 | E18: 1000 | F18: 1000 | G18: 1000 | H18: =SUM(B18:G18) -> 6000
A19: 45444 | B19: 1000 | C19: 1000 | D19: 1000 | E19: 1000 | F19: 1000 | G19: 1000 | H19: =SUM(B19:G19) -> 6000
A20: 45474 | B20: 1000 | C20: 1000 | D20: 1000 | E20: 1000 | F20: 1000 | G20: 1000 | H20: =SUM(B20:G20) -> 6000
A21: 45505 | B21: 1000 | C21: 1000 | D21: 1000 | E21: 1000 | F21: 1000 | G21: 1000 | H21: =SUM(B21:G21) -> 6000
A22: 45536 | B22: 1000 | C22: 1000 | D22: 1000 | E22: 1000 | F22: 1000 | G22: 1000 | H22: =SUM(B22:G22) -> 6000
... A41: 46113 | B41: 1000 | C41: 1000 | D41: 1000 | E41: 1000 | F41: 1000 | G41: 1000 | H41: =SUM(B41:G41) -> 6000
A42: 46143
A43: 46174 | F43: 1000
A44: 46204
A45: 46235
A46: 46266
A47: 46296
A48: 46327
A49: 46357
A50: Total | B50: =SUM(B5:B49) -> 36000 | C50: =SUM(C5:C49) -> 36000 | D50: =SUM(D5:D49) -> 36000 | E50: =SUM(E5:E49) -> 37000 | F50: =SUM(F5:F49) -> 36000 | G50: =SUM(G5:G49) -> 35000 | H50: =SUM(H5:H49) -> 215000

Sheet Expenses
A1: / | B1: Expense | C1: Description | D1: Amount
A2: 44335 | B2: Electricity Bill | C2: April Electricity Bill | D2: 2590
A3: 44329 | B3: Maintenance | C3: Safaiwala May Pagar | D3: 800
A4: 44341 | B4: Maintenance | C4: 3 Water Tank Cleaning | D4: 3500
A5: 44342 | B5: Expense | C5: Water Tanker | D5: 1800
A6: 44343 | B6: Electricity Bill | C6: May Electricity Bill | D6: 1800
A7: 44340 | B7: Maintenance | C7: Water Tank Repair Material | D7: 1430
A8: 44341 | B8: Maintenance | C8: Ground Tank Sliding | D8: 1500
A9: 44348 | B9: Maintenance | C9: Light Bulb, Focus and material | D9: 4650
A10: 44348 | B10: Maintenance | C10: Krishna Electrician Labour cost | D10: 600
A11: 44360 | B11: Maintenance | C11: Safaiwala June Pagar | D11: 800
A12: 44365 | B12: Maintenance | C12: Safaiwala jhadu supdi | D12: 150
A13: 44366 | B13: Maintenance | C13: New Overhead Boring Tank Delivery Labour | D13: 500
... A248: 46149 | B248: Salary | C248: Bharat Pagar | D248: 4500
C276: Total | D276: =SUM(D2:D275) -> 1202585

Sheet Income
F1: Society dues
B2: Date | C2: Description | D2: Amount | F2: Date | G2: Description | H2: Amount | I2: Due To | J2: Due Amount | K2: Status | L2: Paid on
B3: 44808 | C3: Iyer Sir Maintenance Cheque 136601 | D3: 30000 | F3: 45092 | G3: 201 Property Tax | H3: 4900 | I3: Arif Khan | J3: 0 | K3: Paid | L3: 45437
B4: 44834 | C4: Interest in account | D4: 102 | F4: 45108 | G4: Peena ka paani khichne waali Motor | H4: 16170 | I4: Arif Khan | J4: 0 | K4: Paid | L4: 45437
B5: 44857 | C5: Purane Taaki dhakkan bhangar | D5: 300 | F5: 45132 | G5: 306 Property Tax | H5: 24780 | I5: Arif Khan | J5: 0 | K5: Paid | L5: 45437
B6: 44879 | C6: Iyer Sir Maintenance Cheque | D6: 35000 | F6: 45385 | G6: 401 Property Tax | H6: 7875 | I6: Arif Khan | J6: 0 | K6: Paid | L6: 45437
B7: 44913 | C7: FD Interest | D7: 267 | F7: 45425 | G7: 401 Water Bill | H7: 7920 | I7: Arif Khan | J7: 0 | K7: Paid | L7: 45437
B8: 44913 | C8: From CCTV collection | D8: 72000
B9: 44926 | C9: Interest in account | D9: 290
B10: 44988 | C10: FD Interest | D10: 291
B11: 45016 | C11: Interest in account | D11: 415
B12: 45082 | C12: Iyer Sir Maintenance Cheque | D12: 50000
B13: 45107 | C13: Interest in account | D13: 348
B14: 45199 | C14: Interest in account | D14: 696
B15: 45291 | C15: Interest in account | D15: 607
B16: 45382 | C16: Interest in account | D16: 495
B17: 45440 | C17: CCTV damage recovery | D17: 8000
B18: 45467 | C18: Iyer Sir Maintenance | D18: 50000
B19: 45473 | C19: Interest in account | D19: 647
... B33: 46112 | C33: Interest in account | D33: 193
C36: Total | D36: =SUM(D3:D35) -> 432868 | I36: Total | J36: =SUMIF(K3:K27,"Unpaid",J3:J27) -> 0

Sheet Sheet4
A1: Property Tax and Water bill
A2: Room No. | B2: Date | C2: 1 Year property tax | D2: 1 Year Water Bill | E2: Paid | F2: Pending
A3: 205 | B3: 45375 | C3: 3000 | D3: 2640 | E3: =SUM(C3,D3) -> 5640 | F3: 0
A4: 204 | B4: 45375 | C4: 4200 | D4: 2400 | E4: =SUM(C4,D4) -> 6600 | F4: 0
A5: 301 | B5: 45375 | C5: 2625 | D5: 2640 | E5: =SUM(C5,D5) -> 5265 | F5: 0
A6: 201 | B6: 45375 | C6: 2625 | D6: 2640 | E6: =SUM(C6,D6) -> 5265 | F6: 5000
A7: 402 | B7: 45375 | C7: 5812 | D7: 2640 | E7: =SUM(C7,D7) -> 8452 | F7: 0
A8: 302 | B8: 45375 | C8: 5812 | D8: 2640 | E8: =SUM(C8,D8) -> 8452 | F8: 0
A9: 303 | B9: 45375 | C9: 4125 | D9: 2640 | E9: =SUM(C9,D9) -> 6765 | F9: 0
A10: 405 | B10: 45375 | C10: 3000 | D10: 2640 | E10: =SUM(C10,D10) -> 5640 | F10: 0
A11: 106 | B11: 45375 | C11: 4275 | D11: 2640 | E11: =SUM(C11,D11) -> 6915 | F11: 0
A12: 107 | B12: 45375 | C12: 4125 | D12: 2640 | E12: =SUM(C12,D12) -> 6765 | F12: 0
A13: 403 | B13: 45375 | C13: 4125 | D13: 2640 | E13: =SUM(C13,D13) -> 6765 | F13: 0
A14: 404 | B14: 45375 | C14: 4200 | D14: 2640 | E14: =SUM(C14,D14) -> 6840 | F14: 0
... A17: 1 | B17: 45375 | C17: 2625 | D17: 0 | E17: =SUM(C17,D17) -> 2625 | F17: 0
A18: Builder 4 Gala | B18: 45375 | C18: 10500 | D18: 0 | E18: =SUM(C18,D18) -> 10500 | F18: 0

Sheet Maintenance
A1: M/s Bhavani Paradise
A2: Bhavani Paradise, Ravikiran society, Chera Nagar, Manpada rd., Dombivli East - 421 201
A3: Monthly Maintenance
A4: Flat No \ Month-Year | B4: 101 | C4: 102 | D4: 201 | E4: 203 | F4: 204 | G4: 205 | H4: 207 | I4: 301 | J4: 302 | K4: 303 | L4: 306 | M4: 307 | N4: 401 | O4: 405 | P4: 206 | Q4: 502 | R4: 402 | S4: 001 | T4: 202 | U4: Total
A5: 44337 | C5: 500 | D5: 500 | G5: 500 | I5: 500 | J5: 500 | K5: 500 | L5: 500 | N5: 500 | O5: 500 | U5: =SUM(B5:S5) -> 4500
A6: 44368 | C6: 500 | D6: 500 | G6: 500 | I6: 500 | J6: 500 | K6: 500 | L6: 500 | N6: 500 | O6: 500 | U6: =SUM(B6:S6) -> 4500
A7: 44398 | C7: 500 | D7: 500 | G7: 500 | I7: 700 | J7: 1000 | K7: 500 | L7: 500 | N7: 500 | O7: 500 | U7: =SUM(B7:S7) -> 5200
A8: 44429 | C8: 500 | D8: 500 | G8: 500 | I8: 700 | J8: 1000 | K8: 500 | L8: 500 | N8: 700 | O8: 500 | U8: =SUM(B8:S8) -> 5400
A9: 44460 | C9: 500 | D9: 700 | G9: 800 | I9: 700 | J9: 1000 | K9: 500 | L9: 500 | N9: 700 | O9: 500 | U9: =SUM(B9:S9) -> 5900
A10: 44490 | C10: 500 | D10: 700 | G10: 800 | I10: 700 | J10: 1000 | K10: 500 | L10: 500 | N10: 700 | O10: 500 | U10: =SUM(B10:S10) -> 5900
A11: 44521 | C11: 500 | D11: 700 | G11: 800 | I11: 700 | J11: 1000 | K11: 500 | L11: 500 | N11: 700 | O11: 500 | U11: =SUM(B11:S11) -> 5900
A12: 44551 | C12: 500 | D12: 700 | G12: 800 | H12: 700 | I12: 700 | J12: 1000 | K12: 500 | L12: 500 | N12: 700 | O12: 500 | U12: =SUM(B12:S12) -> 6600
A13: 44582 | C13: 500 | D13: 700 | G13: 800 | H13: 700 | I13: 700 | J13: 1000 | K13: 500 | L13: 500 | N13: 700 | O13: 500 | U13: =SUM(B13:S13) -> 6600
A14: 44613 | C14: 500 | D14: 700 | G14: 800 | H14: 700 | I14: 700 | J14: 1000 | K14: 500 | L14: 500 | N14: 700 | O14: 500 | U14: =SUM(B14:S14) -> 6600
A15: 44641 | C15: 500 | D15: 700 | G15: 800 | H15: 700 | I15: 700 | J15: 1000 | K15: 550 | L15: 500 | N15: 700 | O15: 500 | U15: =SUM(B15:S15) -> 6650
A16: 44672 | C16: 775 | D16: 350 | E16: 550 | F16: 560 | G16: 400 | H16: 550 | I16: 350 | J16: 775 | K16: 550 | L16: 570 | M16: 550 | N16: 350 | O16: 400 | U16: =SUM(B16:S16) -> 6730
A17: 44702 | C17: 775 | D17: 350 | E17: 550 | F17: 560 | G17: 400 | H17: 550 | I17: 350 | J17: 775 | K17: 550 | L17: 570 | M17: 550 | N17: 350 | O17: 400 | U17: =SUM(B17:S17) -> 6730
A18: 44734 | C18: 775 | D18: 350 | E18: 550 | F18: 560 | G18: 400 | H18: 550 | I18: 350 | J18: 775 | K18: 550 | L18: 570 | M18: 550 | N18: 350 | O18: 400 | U18: =SUM(B18:S18) -> 6730
A19: 44764 | C19: 775 | D19: 350 | E19: 550 | F19: 560 | G19: 400 | H19: 550 | I19: 350 | J19: 775 | K19: 550 | L19: 570 | M19: 550 | N19: 350 | O19: 400 | U19: =SUM(B19:S19) -> 6730
U20: =SUM(B20:S20) -> 0
U21: =SUM(B21:S21) -> 0
U22: =SUM(B22:S22) -> 0
U23: =SUM(B23:S23) -> 0
U24: =SUM(B24:S24) -> 0
U25: =SUM(B25:S25) -> 0
A26: 44795 | C26: 1100 | D26: 800 | F26: 1000 | G26: 800 | H26: 550 | I26: 800 | J26: 1100 | K26: 1000 | L26: 1000 | M26: 1000 | N26: 800 | O26: 800 | U26: =SUM(B26:S26) -> 10750
A27: 44826 | C27: 1100 | D27: 800 | F27: 1000 | G27: 800 | H27: 1000 | I27: 800 | J27: 1100 | K27: 1000 | L27: 1000 | M27: 1000 | N27: 800 | O27: 800 | U27: =SUM(B27:S27) -> 11200
A28: 44856 | B28: 0 | C28: 1100 | D28: 800 | F28: 1000 | G28: 800 | H28: 1000 | I28: 800 | J28: 1100 | K28: 1000 | L28: 1000 | M28: 1000 | N28: 800 | O28: 800 | U28: =SUM(B28:S28) -> 11200
A29: 44887 | B29: 800 | C29: 1100 | D29: 800 | F29: 1000 | G29: 800 | H29: 1000 | I29: 800 | J29: 1100 | K29: 1000 | L29: 1000 | M29: 1000 | N29: 800 | O29: 800 | U29: =SUM(B29:S29) -> 12000
A30: 44917 | B30: 800 | C30: 1100 | D30: 800 | F30: 1000 | G30: 800 | H30: 1000 | I30: 800 | J30: 1100 | K30: 1000 | L30: 1000 | M30: 1000 | N30: 800 | O30: 800 | U30: =SUM(B30:S30) -> 12000
B31: 2023
A32: 44949 | B32: 800 | C32: 1100 | D32: 800 | F32: 1000 | G32: 800 | H32: 1000 | I32: 800 | J32: 1100 | K32: 1000 | L32: 1000 | M32: 1000 | N32: 800 | O32: 800 | Q32: 1100 | R32: 1100 | U32: =SUM(B32:S32) -> 14200
A33: 44980 | B33: 800 | C33: 1100 | D33: 800 | F33: 1000 | G33: 800 | H33: 1000 | I33: 800 | J33: 1100 | K33: 1000 | L33: 1000 | M33: 1000 | N33: 800 | O33: 800 | Q33: 1100 | R33: 1100 | U33: =SUM(B33:S33) -> 14200
A34: 45008 | B34: 800 | C34: 1100 | D34: 800 | F34: 1000 | G34: 800 | H34: 1000 | I34: 800 | J34: 1100 | K34: 1000 | L34: 1000 | M34: 1000 | N34: 800 | O34: 800 | Q34: 1100 | R34: 1100 | U34: =SUM(B34:S34) -> 14200
A35: 45039 | B35: 800 | C35: 1100 | D35: 800 | F35: 1000 | G35: 800 | H35: 1000 | I35: 800 | J35: 1100 | K35: 1000 | L35: 1000 | M35: 1000 | N35: 800 | O35: 800 | P35: 1000 | Q35: 1100 | R35: 1100 | U35: =SUM(B35:S35) -> 15200
A36: 45069 | B36: 800 | C36: 1100 | D36: 800 | F36: 1000 | G36: 800 | H36: 1000 | I36: 800 | J36: 1100 | K36: 1000 | L36: 1000 | M36: 1000 | N36: 800 | O36: 800 | P36: 1000 | Q36: 1100 | R36: 1100 | U36: =SUM(B36:S36) -> 15200
A37: 45100 | B37: 800 | C37: 1100 | D37: 800 | F37: 1000 | G37: 800 | H37: 1000 | I37: 800 | J37: 1100 | K37: 1000 | L37: 1000 | M37: 1000 | N37: 800 | O37: 800 | P37: 1000 | Q37: 1100 | R37: 1100 | U37: =SUM(B37:S37) -> 15200
A38: 45130 | B38: 800 | C38: 1100 | D38: 800 | F38: 1000 | G38: 800 | H38: 1000 | I38: 800 | J38: 1100 | K38: 1000 | L38: 1000 | M38: 1000 | N38: 800 | O38: 800 | P38: 1000 | Q38: 1100 | R38: 1100 | U38: =SUM(B38:S38) -> 15200
A39: 45161 | B39: 800 | C39: 1100 | D39: 800 | F39: 1000 | G39: 800 | H39: 1000 | I39: 800 | J39: 1100 | K39: 1000 | L39: 1000 | M39: 1000 | N39: 800 | O39: 800 | P39: 1000 | Q39: 1100 | R39: 1100 | U39: =SUM(B39:S39) -> 15200
A40: 45192 | B40: 800 | C40: 1100 | D40: 800 | F40: 1000 | G40: 800 | H40: 1000 | I40: 800 | J40: 1100 | K40: 1000 | L40: 1000 | M40: 1000 | N40: 800 | O40: 800 | P40: 1000 | Q40: 1100 | R40: 1100 | U40: =SUM(B40:S40) -> 15200
...

Sheet Room Details
A1: Bhavani Paradise Room Details
B3: Room No | C3: Owner Name | D3: Area(Sq.Ft.) | E3: Move In Date
B4: 101 | C4: Iyer Sir | D4: 350 | E4: 44713
B5: 101 | C5: Sandeep Kedaskar | D5: 350 | E5: 44835
B6: 102 | C6: Vijay Sawant | D6: 775 | E6: 43466
B7: 103 | C7: Iyer Sir | D7: 550 | E7: 44713
B8: 104 | C8: Iyer Sir | D8: 560 | E8: 44774
B9: 105 | C9: Iyer Sir | D9: 400 | E9: 44713
B10: 106 | C10: Builder | D10: 570 | E10: NA
B11: 107 | C11: Builder | D11: 550 | E11: NA
B12: 201 | C12: Mushtak Shaikh | D12: 350 | E12: 43831
B13: 202 | C13: Iyer Sir | D13: 775 | E13: 44774
B14: 202 | C14: Vaibhavi More | D14: 775 | E14: 45992
B15: 203 | C15: Umesh Chabuk | D15: 550 | E15: 2019
B16: 204 | C16: Avinash Jaiswal | D16: 560 | E16: 2020
B17: 205 | C17: Lokesh Gupta | D17: 400 | E17: 43484
B18: 206 | C18: Iyer Sir | D18: 570 | E18: 44743
B19: 206 | C19: Vaibhavi More | D19: 570 | E19: 45017
B20: 206 | C20: Iyer Sir | D20: 570 | E20: 45992
B21: 207 | C21: Rahul Utekar | D21: 550 | E21: 44531
B22: 301 | C22: Sitaram Kamble | D22: 350 | E22: 43484
B23: 302 | C23: Amit Vyas | D23: 775 | E23: 43484
... B31: 402 | C31: Suresh Vyas | D31: 775 | E31: 45383
B32: 403 | C32: Builder | D32: 550 | E32: NA
B33: 404 | C33: Builder | D33: 550 | E33: NA
B34: 405 | C34: Mahendra Vyas | D34: 400 | E34: 43770
B35: 406 | C35: Iyer Sir | D35: 570 | E35: 44743
B36: 407 | C36: Iyer Sir | D36: 550 | E36: 44713
B37: 501 | C37: Iyer Sir | D37: 350 | E37: 44774
B38: 502 | C38: Ajay Pandey | D38: 775 | E38: 44927
B39: 503 | C39: Iyer Sir | D39: 550 | E39: 44774
B40: 504 | C40: Builder | D40: 560 | E40: NA
B41: 505 | C41: Iyer Sir | D41: 400 | E41: 44713
B42: 506 | C42: Iyer Sir | D42: 550 | E42: 44774
B43: 507 | C43: Builder | D43: 550 | E43: NA

Sheet Maintenance_Mar26
B2: Room No | C2: Owner Name | D2: Monthly Maintenance | E2: Pending From | F2: Pending To | G2: Total Pending Months | H2: Total Pending Amount
B3: 101 | C3: Kedaskar | D3: 800 | E3: 45383 | F3: 46054 | G3: =DATEDIF(E3,F3,"M")+1 -> 23 | H3: =D3*G3 -> 18400
B4: 102 | C4: Sawant | D4: 1100 | E4: 45292 | F4: 46054 | G4: =DATEDIF(E4,F4,"M")+1 -> 26 | H4: =D4*G4 -> 28600
B5: 103 | C5: Iyer Sir | D5: 1000 | E5: 45627 | F5: 46054 | G5: =DATEDIF(E5,F5,"M")+1 -> 15 | H5: =D5*G5 -> 15000
B6: 104 | C6: Iyer Sir | D6: 1000 | E6: 45627 | F6: 46054 | G6: =DATEDIF(E6,F6,"M")+1 -> 15 | H6: =D6*G6 -> 15000
B7: 105 | C7: Iyer Sir | D7: 800 | E7: 45627 | F7: 46054 | G7: =DATEDIF(E7,F7,"M")+1 -> 15 | H7: =D7*G7 -> 12000
B8: 106 | C8: Builder | D8: 1000 | E8: 46054 | F8: 46054 | G8: =DATEDIF(E8,F8,"M")+1 -> 1 | H8: =D8*G8 -> 1000
B9: 107 | C9: Builder | D9: 1000 | E9: 46054 | F9: 46054 | G9: =DATEDIF(E9,F9,"M")+1 -> 1 | H9: =D9*G9 -> 1000
B10: 201 | C10: Mushtak Shaikh | D10: 800 | E10: 45992 | F10: 46054 | G10: =DATEDIF(E10,F10,"M")+1 -> 3 | H10: =D10*G10 -> 2400
B11: 202 | C11: Iyer Sir | D11: 1100 | E11: 45627 | F11: 45962 | G11: =DATEDIF(E11,F11,"M")+1 -> 12 | H11: =D11*G11 -> 13200
B12: 202 | C12: Vaibhavi More | D12: 1100 | E12: 46054 | F12: 46054 | G12: =DATEDIF(E12,F12,"M")+1 -> 1 | H12: =D12*G12 -> 1100
B13: 203 | C13: Umesh Chabuk | D13: 1000 | E13: 44774 | F13: 46054 | G13: =DATEDIF(E13,F13,"M")+1 -> 43 | H13: =D13*G13 -> 43000
B14: 204 | C14: Avinash Jaiswal | D14: 1000 | E14: 45901 | F14: 46054 | G14: =DATEDIF(E14,F14,"M")+1 -> 6 | H14: =D14*G14 -> 6000
B15: 205 | C15: Lokesh Gupta | D15: 800 | E15: 45292 | F15: 46054 | G15: =DATEDIF(E15,F15,"M")+1 -> 26 | H15: =D15*G15 -> 20800
B16: 206 | C16: Iyer Sir | D16: 1000 | E16: 45992 | F16: 46054 | G16: =DATEDIF(E16,F16,"M")+1 -> 3 | H16: =D16*G16 -> 3000
... B22: 305 | C22: Iyer Sir | D22: 800 | E22: 45627 | F22: 46054 | G22: =DATEDIF(E22,F22,"M")+1 -> 15 | H22: =D22*G22 -> 12000
B23: 306 | C23: Dilip Kadam | D23: 1000 | H23: =D23*G23 -> 0
B24: 307 | C24: Vijay Kumar | D24: 1000 | H24: =D24*G24 -> 0
B25: 401 | C25: Omkar Gadekar | D25: 800 | E25: 45992 | F25: 46054 | G25: =DATEDIF(E25,F25,"M")+1 -> 3 | H25: =D25*G25 -> 2400
B26: 402 | C26: Suresh Vyas | D26: 1100 | E26: 45383 | F26: 46054 | G26: =DATEDIF(E26,F26,"M")+1 -> 23 | H26: =D26*G26 -> 25300
B27: 403 | C27: Builder | D27: 1000 | E27: 46054 | F27: 46054 | G27: =DATEDIF(E27,F27,"M")+1 -> 1 | H27: =D27*G27 -> 1000
B28: 404 | C28: Builder | D28: 1000 | E28: 46054 | F28: 46054 | G28: =DATEDIF(E28,F28,"M")+1 -> 1 | H28: =D28*G28 -> 1000
B29: 405 | C29: Mahendra Vyas | D29: 800 | E29: 45870 | F29: 46054 | G29: =DATEDIF(E29,F29,"M")+1 -> 7 | H29: =D29*G29 -> 5600
B30: 406 | C30: Iyer Sir | D30: 1000 | E30: 45627 | F30: 46054 | G30: =DATEDIF(E30,F30,"M")+1 -> 15 | H30: =D30*G30 -> 15000
B31: 407 | C31: Iyer Sir | D31: 1000 | E31: 45627 | F31: 46054 | G31: =DATEDIF(E31,F31,"M")+1 -> 15 | H31: =D31*G31 -> 15000
B32: 501 | C32: Iyer Sir | D32: 800 | E32: 45627 | F32: 46054 | G32: =DATEDIF(E32,F32,"M")+1 -> 15 | H32: =D32*G32 -> 12000
B33: 502 | C33: Ajay Pandey | D33: 1100 | E33: 45748 | F33: 46054 | G33: =DATEDIF(E33,F33,"M")+1 -> 11 | H33: =D33*G33 -> 12100
B34: 503 | C34: Iyer Sir | D34: 1000 | E34: 45627 | F34: 46054 | G34: =DATEDIF(E34,F34,"M")+1 -> 15 | H34: =D34*G34 -> 15000
B35: 504 | C35: Builder | D35: 1000 | E35: 46054 | F35: 46054 | G35: =DATEDIF(E35,F35,"M")+1 -> 1 | H35: =D35*G35 -> 1000
B36: 505 | C36: Iyer Sir | D36: 800 | E36: 45627 | F36: 46054 | G36: =DATEDIF(E36,F36,"M")+1 -> 15 | H36: =D36*G36 -> 12000
B37: 506 | C37: Iyer Sir | D37: 1000 | E37: 45627 | F37: 46054 | G37: =DATEDIF(E37,F37,"M")+1 -> 15 | H37: =D37*G37 -> 15000
B38: 507 | C38: Builder | D38: 1000 | E38: 46054 | F38: 46054 | G38: =DATEDIF(E38,F38,"M")+1 -> 1 | H38: =D38*G38 -> 1000
G40: Total | H40: =SUM(H3:H38) -> 407300

Sheet Maintenance_May26
B2: Room No | C2: Owner Name | D2: Monthly Maintenance | E2: Pending From | F2: Pending To | G2: Total Pending Months | H2: Total Pending Amount
B3: 101 | C3: Kedaskar | D3: 800 | E3: 45536 | F3: 46113 | G3: =DATEDIF(E3,F3,"M")+1 -> 20 | H3: =D3*G3 -> 16000
B4: 102 | C4: Sawant | D4: 1100 | E4: 45292 | F4: 46113 | G4: =DATEDIF(E4,F4,"M")+1 -> 28 | H4: =D4*G4 -> 30800
B5: 103 | C5: Iyer Sir | D5: 1000 | E5: 45627 | F5: 46113 | G5: =DATEDIF(E5,F5,"M")+1 -> 17 | H5: =D5*G5 -> 17000
B6: 104 | C6: Iyer Sir | D6: 1000 | E6: 45627 | F6: 46113 | G6: =DATEDIF(E6,F6,"M")+1 -> 17 | H6: =D6*G6 -> 17000
B7: 105 | C7: Iyer Sir | D7: 800 | E7: 45627 | F7: 46113 | G7: =DATEDIF(E7,F7,"M")+1 -> 17 | H7: =D7*G7 -> 13600
B8: 106 | C8: Builder | D8: 1000 | H8: =D8*G8 -> 0
B9: 107 | C9: Builder | D9: 1000 | H9: =D9*G9 -> 0
B10: 201 | C10: Mushtak Shaikh | D10: 800 | E10: 45992 | F10: 46113 | G10: =DATEDIF(E10,F10,"M")+1 -> 5 | H10: =D10*G10 -> 4000
B11: 202 | C11: Iyer Sir | D11: 1100 | E11: 45627 | F11: 45962 | G11: =DATEDIF(E11,F11,"M")+1 -> 12 | H11: =D11*G11 -> 13200
B12: 202 | C12: Vaibhavi More | D12: 1100 | E12: 46113 | F12: 46113 | G12: =DATEDIF(E12,F12,"M")+1 -> 1 | H12: =D12*G12 -> 1100
B13: 203 | C13: Umesh Chabuk | D13: 1000 | E13: 44774 | F13: 46113 | G13: =DATEDIF(E13,F13,"M")+1 -> 45 | H13: =D13*G13 -> 45000
B14: 204 | C14: Avinash Jaiswal | D14: 1000 | H14: =D14*G14 -> 0
B15: 205 | C15: Lokesh Gupta | D15: 800 | E15: 45292 | F15: 46113 | G15: =DATEDIF(E15,F15,"M")+1 -> 28 | H15: =D15*G15 -> 22400
B16: 206 | C16: Iyer Sir | D16: 1000 | E16: 45992 | F16: 46113 | G16: =DATEDIF(E16,F16,"M")+1 -> 5 | H16: =D16*G16 -> 5000
B17: 207 | C17: Rahul Utekar | D17: 1000 | E17: 45323 | F17: 46113 | G17: =DATEDIF(E17,F17,"M")+1 -> 27 | H17: =D17*G17 -> 27000
B18: 301 | C18: Sitaram Kamble | D18: 800 | E18: 45474 | F18: 46113 | G18: =DATEDIF(E18,F18,"M")+1 -> 22 | H18: =D18*G18 -> 17600
B19: 302 | C19: Amit Vyas | D19: 1100 | H19: =D19*G19 -> 0
B20: 303 | C20: Bharat Vyas | D20: 1000 | H20: =D20*G20 -> 0
B21: 304 | C21: Iyer Sir | D21: 1000 | E21: 45627 | F21: 46113 | G21: =DATEDIF(E21,F21,"M")+1 -> 17 | H21: =D21*G21 -> 17000
B22: 305 | C22: Iyer Sir | D22: 800 | E22: 45627 | F22: 46113 | G22: =DATEDIF(E22,F22,"M")+1 -> 17 | H22: =D22*G22 -> 13600
B23: 306 | C23: Dilip Kadam | D23: 1000 | E23: 46113 | F23: 46113 | G23: =DATEDIF(E23,F23,"M")+1 -> 1 | H23: =D23*G23 -> 1000
B24: 307 | C24: Vijay Kumar | D24: 1000 | H24: =D24*G24 -> 0
B25: 401 | C25: Omkar Gadekar | D25: 800 | E25: 46082 | F25: 46113 | G25: =DATEDIF(E25,F25,"M")+1 -> 2 | H25: =D25*G25 -> 1600
B26: 402 | C26: Suresh Vyas | D26: 1100 | E26: 45383 | F26: 46113 | G26: =DATEDIF(E26,F26,"M")+1 -> 25 | H26: =D26*G26 -> 27500
B27: 403 | C27: Builder | D27: 1000 | H27: =D27*G27 -> 0
B28: 404 | C28: Builder | D28: 1000 | H28: =D28*G28 -> 0
B29: 405 | C29: Mahendra Vyas | D29: 800 | E29: 46113 | F29: 46113 | G29: =DATEDIF(E29,F29,"M")+1 -> 1 | H29: =D29*G29 -> 800
B30: 406 | C30: Iyer Sir | D30: 1000 | E30: 45627 | F30: 46113 | G30: =DATEDIF(E30,F30,"M")+1 -> 17 | H30: =D30*G30 -> 17000
B31: 407 | C31: Iyer Sir | D31: 1000 | E31: 45627 | F31: 46113 | G31: =DATEDIF(E31,F31,"M")+1 -> 17 | H31: =D31*G31 -> 17000
B32: 501 | C32: Iyer Sir | D32: 800 | E32: 45627 | F32: 46113 | G32: =DATEDIF(E32,F32,"M")+1 -> 17 | H32: =D32*G32 -> 13600
B33: 502 | C33: Ajay Pandey | D33: 1100 | E33: 45748 | F33: 46113 | G33: =DATEDIF(E33,F33,"M")+1 -> 13 | H33: =D33*G33 -> 14300
B34: 503 | C34: Iyer Sir | D34: 1000 | E34: 45627 | F34: 46113 | G34: =DATEDIF(E34,F34,"M")+1 -> 17 | H34: =D34*G34 -> 17000
B35: 504 | C35: Builder | D35: 1000 | H35: =D35*G35 -> 0
B36: 505 | C36: Iyer Sir | D36: 800 | E36: 45627 | F36: 46113 | G36: =DATEDIF(E36,F36,"M")+1 -> 17 | H36: =D36*G36 -> 13600
B37: 506 | C37: Iyer Sir | D37: 1000 | E37: 45627 | F37: 46113 | G37: =DATEDIF(E37,F37,"M")+1 -> 17 | H37: =D37*G37 -> 17000
B38: 507 | C38: Builder | D38: 1000 | H38: =D38*G38 -> 0
G40: Total | H40: =SUM(H3:H38) -> 400700

Sheet Account change
B1: Till July End
B2: Description | C2: Amount | F2: Audit History
B3: Maintenance Received | C3: 95920 | F3: Date | G3: Balance | H3: Remark
B4: CCTV Payments | C4: 15000 | F4: 45962 | G4: 66774 | H4: Account Matched
B5: Expenses | C5: -96018
B14: Total | C14: =SUM(C3:C13) -> 14902
